<?xml version="1.0" ?>
<robot name="newrobot" xmlns:xacro="http://www.ros.org/wiki/xacro">

<xacro:include filename="$(find newrobot_description)/urdf/materials.xacro" />
<xacro:include filename="$(find newrobot_description)/urdf/newrobot.trans" />
<xacro:include filename="$(find newrobot_description)/urdf/newrobot.gazebo" />
<link name="base_link">
  <inertial>
    <origin xyz="0.0038775828308717252 -1.6665797136639413e-17 0.052918293473760994" rpy="0 0 0"/>
    <mass value="2.3138752403503777"/>
    <inertia ixx="0.007906" iyy="0.008397" izz="0.014792" ixy="-0.0" iyz="-0.0" ixz="-0.000337"/>
  </inertial>
  <visual>
    <origin xyz="0 0 0" rpy="0 0 0"/>
    <geometry>
      <mesh filename="package://newrobot_description/meshes/base_link.stl" scale="0.001 0.001 0.001"/>
    </geometry>
    <material name="silver"/>
  </visual>
  <collision>
    <origin xyz="0 0 0" rpy="0 0 0"/>
    <geometry>
      <mesh filename="package://newrobot_description/meshes/base_link.stl" scale="0.001 0.001 0.001"/>
    </geometry>
  </collision>
</link>

<link name="right_wheel_1">
  <inertial>
    <origin xyz="1.737006930036608e-17 -0.012499999999999997 0.0" rpy="0 0 0"/>
    <mass value="0.18260507298990675"/>
    <inertia ixx="0.000124" iyy="0.000228" izz="0.000124" ixy="0.0" iyz="-0.0" ixz="0.0"/>
  </inertial>
  <visual>
    <origin xyz="-0.0 0.1 -0.05" rpy="0 0 0"/>
    <geometry>
      <mesh filename="package://newrobot_description/meshes/right_wheel_1.stl" scale="0.001 0.001 0.001"/>
    </geometry>
    <material name="silver"/>
  </visual>
  <collision>
    <origin xyz="-0.0 0.1 -0.05" rpy="0 0 0"/>
    <geometry>
      <mesh filename="package://newrobot_description/meshes/right_wheel_1.stl" scale="0.001 0.001 0.001"/>
    </geometry>
  </collision>
</link>

<link name="left_wheel_1">
  <inertial>
    <origin xyz="1.737006930036608e-17 0.012499999999999997 0.0" rpy="0 0 0"/>
    <mass value="0.18260507298990675"/>
    <inertia ixx="0.000124" iyy="0.000228" izz="0.000124" ixy="-0.0" iyz="0.0" ixz="0.0"/>
  </inertial>
  <visual>
    <origin xyz="-0.0 -0.1 -0.05" rpy="0 0 0"/>
    <geometry>
      <mesh filename="package://newrobot_description/meshes/left_wheel_1.stl" scale="0.001 0.001 0.001"/>
    </geometry>
    <material name="silver"/>
  </visual>
  <collision>
    <origin xyz="-0.0 -0.1 -0.05" rpy="0 0 0"/>
    <geometry>
      <mesh filename="package://newrobot_description/meshes/left_wheel_1.stl" scale="0.001 0.001 0.001"/>
    </geometry>
  </collision>
</link>

<link name="lidar_1">
  <inertial>
    <origin xyz="0.0 5.584513020951031e-18 0.012499999999999997" rpy="0 0 0"/>
    <mass value="0.7990326755140279"/>
    <inertia ixx="0.000301" iyy="0.000301" izz="0.000518" ixy="0.0" iyz="-0.0" ixz="0.0"/>
  </inertial>
  <visual>
    <origin xyz="-0.05 -0.0 -0.11" rpy="0 0 0"/>
    <geometry>
      <mesh filename="package://newrobot_description/meshes/lidar_1.stl" scale="0.001 0.001 0.001"/>
    </geometry>
    <material name="silver"/>
  </visual>
  <collision>
    <origin xyz="-0.05 -0.0 -0.11" rpy="0 0 0"/>
    <geometry>
      <mesh filename="package://newrobot_description/meshes/lidar_1.stl" scale="0.001 0.001 0.001"/>
    </geometry>
  </collision>
</link>

<joint name="Rev3" type="continuous">
  <origin xyz="0.0 -0.1 0.05" rpy="0 0 0"/>
  <parent link="base_link"/>
  <child link="right_wheel_1"/>
  <axis xyz="0.0 1.0 0.0"/>
</joint>

<joint name="Rev4" type="continuous">
  <origin xyz="0.0 0.1 0.05" rpy="0 0 0"/>
  <parent link="base_link"/>
  <child link="left_wheel_1"/>
  <axis xyz="0.0 1.0 0.0"/>
</joint>

<joint name="Rigid5" type="fixed">
  <origin xyz="0.05 0.0 0.11" rpy="0 0 0"/>
  <parent link="base_link"/>
  <child link="lidar_1"/>
</joint>

</robot>
